#VRML_SIM R2020a utf8
WorldInfo {
  info [
    "Example of use of two Camera devices to produce stereoscopy"
  ]
  title "Binocular"
  basicTimeStep 16
}
Viewpoint {
  orientation 0.11934408320082561 0.9856655851449738 0.11924908412969423 4.6987475853186735
  position -2.3325103306748898 0.7690880396581238 -0.0559045282353047
  follow "ALPIBOT:solid(1)"
}
TexturedBackground {
}
DirectionalLight {
  ambientIntensity 1
  direction -0.5 -1 0
  intensity 1.5
  castShadows TRUE
}
DirectionalLight {
  ambientIntensity 1
  direction 0 -1 0
  intensity 1.5
  castShadows TRUE
}
DirectionalLight {
  ambientIntensity 1
  direction 0.5 -1 0
  intensity 1.5
  castShadows TRUE
}
RectangleArena {
  floorSize 10 10
}
DEF ALPIBOT Robot {
  translation -0.360104 0 -0.319077
  rotation 0 1 0 0.787
  children [
    DEF GPS_SENSORS Group {
      children [
        GPS {
          translation 0 0.075 0
          name "robot_gps"
        }
        GPS {
          translation 0.095 0.08 0
          children [
            Solid {
              children [
                DEF REEL_SHAPE Shape {
                  appearance PBRAppearance {
                    baseColor 0.42 0.42 0.42
                    roughness 1
                    metalness 0
                  }
                  geometry Box {
                    size 0.02 0.02 0.02
                  }
                }
              ]
              boundingObject USE REEL_SHAPE
            }
          ]
          name "left_gps_sensor"
        }
        GPS {
          translation -0.095 0.08 0
          children [
            Solid {
              children [
                DEF REEL_SHAPE Shape {
                  appearance PBRAppearance {
                    baseColor 0.419608 0.419608 0.419608
                    roughness 1
                    metalness 0
                  }
                  geometry Box {
                    size 0.02 0.02 0.02
                  }
                }
              ]
              boundingObject USE REEL_SHAPE
            }
          ]
          name "right_gps_sensor"
        }
      ]
    }
    Group {
      children [
        Transform {
          translation 0 0 -0.24
          children [
            Solid {
              translation 0 0.041 0
              children [
                Shape {
                  appearance DEF MAKEBLOCK_BLUE BrushedAluminium {
                    colorOverride 0.00784314 0.796078 1
                  }
                  geometry DEF CASTOR_SUPPORT_SHAPE Box {
                    size 0.05 0.006 0.05
                  }
                }
              ]
              name "solid(6)"
              boundingObject USE CASTOR_SUPPORT_SHAPE
              physics Physics {
              }
            }
            BallJoint {
              jointParameters BallJointParameters {
                anchor 0 0.02 0
              }
              endPoint Solid {
                translation 0 0.02 0
                rotation -0.8152677444539514 0.006295982773543924 -0.5790499680112949 3.498045657546045
                children [
                  DEF CASTOR_SPHERE Shape {
                    appearance PBRAppearance {
                      baseColor 0.53 0.53 0.53
                      baseColorMap ImageTexture {
                        url [
                          "textures/texture_grid.png"
                        ]
                      }
                      roughness 1
                    }
                    geometry Sphere {
                      radius 0.02
                    }
                  }
                ]
                name "solid(5)"
                boundingObject USE CASTOR_SPHERE
                physics Physics {
                }
              }
            }
          ]
        }
        Transform {
          translation -0.065 0.04 -0.135
          rotation 0 1 0 4.189
          children [
            DEF BLUE_BAR_SOLID Solid {
              children [
                Shape {
                  appearance USE MAKEBLOCK_BLUE
                  geometry DEF BLUE_BAR_SHAPE Box {
                    size 0.22 0.005 0.025
                  }
                }
              ]
              name "solid(3)"
              boundingObject USE BLUE_BAR_SHAPE
              physics Physics {
              }
            }
          ]
        }
        Transform {
          translation 0.065 0.04 -0.135
          rotation 0 1 0 -4.189
          children [
            DEF BLUE_BAR_SOLID Solid {
              children [
                Shape {
                  appearance USE MAKEBLOCK_BLUE
                  geometry DEF BLUE_BAR_SHAPE Box {
                    size 0.22 0.005 0.025
                  }
                }
              ]
              name "solid(4)"
              boundingObject USE BLUE_BAR_SHAPE
              physics Physics {
              }
            }
          ]
        }
      ]
    }
    Transform {
      translation 0.1125 0.0475 0
      children [
        Solid {
          children [
            DEF WHEEL_BLOCK_SHAPE Shape {
              appearance USE MAKEBLOCK_BLUE
              geometry Box {
                size 0.005 0.06 0.08
              }
            }
          ]
          name "solid(1)"
          boundingObject USE WHEEL_BLOCK_SHAPE
          physics Physics {
          }
        }
      ]
    }
    Transform {
      translation -0.1125 0.0475 0
      children [
        Solid {
          children [
            DEF WHEEL_BLOCK_SHAPE Shape {
              appearance USE MAKEBLOCK_BLUE
              geometry Box {
                size 0.005 0.06 0.08
              }
            }
          ]
          name "solid(2)"
          boundingObject USE WHEEL_BLOCK_SHAPE
          physics Physics {
          }
        }
      ]
    }
    Transform {
      translation 0 0.0725 0
      children [
        DEF BLUE_BAR_SOLID Solid {
          children [
            Shape {
              appearance USE MAKEBLOCK_BLUE
              geometry DEF BLUE_BAR_SHAPE Box {
                size 0.22 0.005 0.025
              }
            }
          ]
          boundingObject USE BLUE_BAR_SHAPE
          physics Physics {
          }
        }
      ]
    }
    HingeJoint {
      jointParameters HingeJointParameters {
        anchor -0.11 0.0325 0
      }
      device [
        RotationalMotor {
          name "right wheel motor"
          acceleration 3
          maxVelocity 20
        }
        PositionSensor {
          name "right wheel sensor"
        }
      ]
      endPoint Solid {
        translation -0.13 0.0325 0
        rotation 1 0 0 0
        children [
          DEF WHEEL Transform {
            rotation 0 0 1 1.57
            children [
              Shape {
                appearance PBRAppearance {
                  baseColor 0.513725 0.513725 0.513725
                  baseColorMap ImageTexture {
                    url [
                      "textures/texture_grid.png"
                    ]
                  }
                  roughness 1
                  metalness 0
                }
                geometry Cylinder {
                  height 0.02
                  radius 0.0325
                }
              }
            ]
          }
        ]
        name "left wheel"
        boundingObject USE WHEEL
        physics DEF PHYSICS_WHEEL Physics {
          density -1
          mass 0.05
        }
      }
    }
    HingeJoint {
      jointParameters HingeJointParameters {
        anchor 0.11 0.0325 0
      }
      device [
        RotationalMotor {
          name "left wheel motor"
          acceleration 3
          maxVelocity 20
        }
        PositionSensor {
          name "left wheel sensor"
        }
      ]
      endPoint Solid {
        translation 0.13 0.03250000000000003 0
        rotation 1 0 0 0
        children [
          USE WHEEL
        ]
        name "right wheel"
        boundingObject USE WHEEL
        physics USE PHYSICS_WHEEL
      }
    }
  ]
  name "ALPIBOT"
  physics Physics {
    density -1
    mass 0.5
  }
  controller "follow_and_turn"
  supervisor TRUE
}
DEF FOLLOWING Solid {
  translation 0 0.06 0
  children [
    Shape {
      appearance GlossyPaint {
        baseColor 0 0.666667 0
      }
      geometry DEF CAPSULE Capsule {
        height 0.08
        radius 0.03
      }
    }
  ]
  boundingObject USE CAPSULE
}
